2024-12-01 22:45:09,854 - WARNING - File: G:/My Drive/Acer Spin Laptop Backup/Documents/Test\Test Document 7.pdf
Page: 1
Category: Encryption Error
Severity: WARNING
Message: document closed or encrypted
Details: Traceback (most recent call last):
  File "C:\PycharmProjects\document_analyzer\pdf_analyzer_gui.py", line 1497, in analyze_pdf_page
    page = pdf[page_num]
           ~~~^^^^^^^^^^
  File "C:\PycharmProjects\DAV\.venv\Lib\site-packages\fitz\fitz.py", line 5798, in __getitem__
    return self.load_page(i)
           ^^^^^^^^^^^^^^^^^
  File "C:\PycharmProjects\DAV\.venv\Lib\site-packages\fitz\fitz.py", line 4172, in load_page
    raise ValueError("document closed or encrypted")
ValueError: document closed or encrypted

Timestamp: 2024-12-01T22:44:55.233121
--------------------------------------------------------------------------------
2024-12-01 22:47:42,327 - WARNING - File: G:/My Drive/Acer Spin Laptop Backup/Documents/Test\Test Document 7.pdf
Page: 1
Category: Encryption Error
Severity: WARNING
Message: document closed or encrypted
Details: Traceback (most recent call last):
  File "C:\PycharmProjects\document_analyzer\pdf_analyzer_gui.py", line 1497, in analyze_pdf_page
    page = pdf[page_num]
           ~~~^^^^^^^^^^
  File "C:\PycharmProjects\DAV\.venv\Lib\site-packages\fitz\fitz.py", line 5798, in __getitem__
    return self.load_page(i)
           ^^^^^^^^^^^^^^^^^
  File "C:\PycharmProjects\DAV\.venv\Lib\site-packages\fitz\fitz.py", line 4172, in load_page
    raise ValueError("document closed or encrypted")
ValueError: document closed or encrypted

Timestamp: 2024-12-01T22:44:55.233121
--------------------------------------------------------------------------------
2024-12-01 22:47:42,726 - WARNING - File: batch writing
Page: N/A
Category: Unknown Error
Severity: WARNING
Message: __cinit__() got an unexpected keyword argument 'metadata'
Details: Traceback (most recent call last):
  File "C:\PycharmProjects\document_analyzer\pdf_analyzer_gui.py", line 1316, in write_batch
    output_file = self.output_handler.write_batch(self.results_batch, is_final)
                  ^^^^^^^^^^^^^^^^^^^^^^^^^^^^^^^^^^^^^^^^^^^^^^^^^^^^^^^^^^^^^
  File "C:\PycharmProjects\document_analyzer\output_handlers.py", line 124, in write_batch
    pq.write_table(
  File "C:\PycharmProjects\DAV\.venv\Lib\site-packages\pyarrow\parquet\core.py", line 3104, in write_table
    with ParquetWriter(
         ^^^^^^^^^^^^^^
  File "C:\PycharmProjects\DAV\.venv\Lib\site-packages\pyarrow\parquet\core.py", line 1016, in __init__
    self.writer = _parquet.ParquetWriter(
                  ^^^^^^^^^^^^^^^^^^^^^^^
  File "pyarrow\\_parquet.pyx", line 1807, in pyarrow._parquet.ParquetWriter.__cinit__
TypeError: __cinit__() got an unexpected keyword argument 'metadata'

Timestamp: 2024-12-01T22:44:55.233121
--------------------------------------------------------------------------------
2024-12-01 22:48:16,591 - WARNING - File: G:/My Drive/Acer Spin Laptop Backup/Documents/Test\Test Document 7.pdf
Page: 1
Category: Encryption Error
Severity: WARNING
Message: document closed or encrypted
Details: Traceback (most recent call last):
  File "C:\PycharmProjects\document_analyzer\pdf_analyzer_gui.py", line 1497, in analyze_pdf_page
    page = pdf[page_num]
           ~~~^^^^^^^^^^
  File "C:\PycharmProjects\DAV\.venv\Lib\site-packages\fitz\fitz.py", line 5798, in __getitem__
    return self.load_page(i)
           ^^^^^^^^^^^^^^^^^
  File "C:\PycharmProjects\DAV\.venv\Lib\site-packages\fitz\fitz.py", line 4172, in load_page
    raise ValueError("document closed or encrypted")
ValueError: document closed or encrypted

Timestamp: 2024-12-01T22:44:55.233121
--------------------------------------------------------------------------------
2024-12-01 22:48:16,939 - ERROR - File: batch writing
Page: N/A
Category: Unknown Error
Severity: ERROR
Message: SQLite objects created in a thread can only be used in that same thread. The object was created in thread id 30104 and this is thread id 22720.
Details: Traceback (most recent call last):
  File "C:\PycharmProjects\document_analyzer\output_handlers.py", line 194, in write_batch
    cursor = self.conn.executemany(
             ^^^^^^^^^^^^^^^^^^^^^^
sqlite3.ProgrammingError: SQLite objects created in a thread can only be used in that same thread. The object was created in thread id 30104 and this is thread id 22720.

During handling of the above exception, another exception occurred:

Traceback (most recent call last):
  File "C:\PycharmProjects\document_analyzer\pdf_analyzer_gui.py", line 1316, in write_batch
    output_file = self.output_handler.write_batch(self.results_batch, is_final)
                  ^^^^^^^^^^^^^^^^^^^^^^^^^^^^^^^^^^^^^^^^^^^^^^^^^^^^^^^^^^^^^
  File "C:\PycharmProjects\document_analyzer\output_handlers.py", line 192, in write_batch
    with self.conn:
         ^^^^^^^^^
sqlite3.ProgrammingError: SQLite objects created in a thread can only be used in that same thread. The object was created in thread id 30104 and this is thread id 22720.

Timestamp: 2024-12-01T22:44:55.233121
--------------------------------------------------------------------------------
